Workbook

Sheet ripping report 
A1: Employee - ID | B1: Employee | C1: Pay run name | D1: Employee gross pay - Currency | E1: Employee gross pay | F1: End date
A2: 655bdaba11259ef04cfc737e | B2: Claire Vogl | C2: January Payroll - US (2024) | D2: USD | E2: 365.5 | F2: 45302
A3: 655bdaba11259ef04cfc737e | B3: Claire Vogl | C3: US Payroll - May (2024) | D3: USD | E3: 671.5 | F3: 45414
A4: 655bdaba11259ef04cfc737e | B4: Claire Vogl | C4: US Payroll - March (2024) | D4: USD | E4: 680 | F4: 45358
A5: 655bdaba11259ef04cfc737e | B5: Claire Vogl | C5: US Payroll - February (2024) | D5: USD | E5: 556.75 | F5: 45330
A6: 655bdaba11259ef04cfc737e | B6: Claire Vogl | C6: April Payroll - US (2024) | D6: USD | E6: 671.5 | F6: 45386
A7: 655bdaba11259ef04cfc737e | B7: Claire Vogl | C7: Q2 2024 reconciliation (2024) | D7: USD | E7: 0
A8: 655bdaba11259ef04cfc737e | B8: Claire Vogl | C8: June Payroll - US (2024) | D8: USD | E8: 788.5 | F8: 45442
A9: 655bdaba11259ef04cfc737e | B9: Claire Vogl | C9: Q1 2024 reconciliation (2024) | D9: USD | E9: 0
A10: 61df113f578e5ca21acf182c | B10: JT Metcalf | C10: April Payroll - US (2024) | D10: USD | E10: 7120 | F10: 45386
A11: 61df113f578e5ca21acf182c | B11: JT Metcalf | C11: Q2 2024 reconciliation (2024) | D11: USD | E11: 0
A12: 61df113f578e5ca21acf182c | B12: JT Metcalf | C12: January Payroll - US (2024) | D12: USD | E12: 7340 | F12: 45302
A13: 61df113f578e5ca21acf182c | B13: JT Metcalf | C13: US Payroll - May (2024) | D13: USD | E13: 7110 | F13: 45414
A14: 61df113f578e5ca21acf182c | B14: JT Metcalf | C14: US Payroll - March (2024) | D14: USD | E14: 7450 | F14: 45358
A15: 61df113f578e5ca21acf182c | B15: JT Metcalf | C15: US Payroll - February (2024) | D15: USD | E15: 7260 | F15: 45330
A16: 61df113f578e5ca21acf182c | B16: JT Metcalf | C16: June Payroll - US (2024) | D16: USD | E16: 6990 | F16: 45442
A17: 61df113f578e5ca21acf182c | B17: JT Metcalf | C17: Q1 2024 reconciliation (2024) | D17: USD | E17: 0
A18: 654d1a4303c91c58da173b58 | B18: Colby Neeb | C18: April Payroll - US (2024) | D18: USD | E18: 6708.46 | F18: 45386
A19: 654d1a4303c91c58da173b58 | B19: Colby Neeb | C19: Q2 2024 reconciliation (2024) | D19: USD | E19: 0
A20: 654d1a4303c91c58da173b58 | B20: Colby Neeb | C20: January Payroll - US (2024) | D20: USD | E20: 7595 | F20: 45302
A21: 654d1a4303c91c58da173b58 | B21: Colby Neeb | C21: US Payroll - May (2024) | D21: USD | E21: 6646.69 | F21: 45414
A22: 654d1a4303c91c58da173b58 | B22: Colby Neeb | C22: US Payroll - March (2024) | D22: USD | E22: 6844.32 | F22: 45358
A23: 654d1a4303c91c58da173b58 | B23: Colby Neeb | C23: US Payroll - February (2024) | D23: USD | E23: 7079.84 | F23: 45330
A24: 654d1a4303c91c58da173b58 | B24: Colby Neeb | C24: June Payroll - US (2024) | D24: USD | E24: 7256.82 | F24: 45442
A25: 654d1a4303c91c58da173b58 | B25: Colby Neeb | C25: Q1 2024 reconciliation (2024) | D25: USD | E25: 0
A26: 65a5aa4d3c9840e32446690c | B26: Vicente Ramos | C26: April Payroll - US (2024) | D26: USD | E26: 1520 | F26: 45386
A27: 65a5aa4d3c9840e32446690c | B27: Vicente Ramos | C27: Q2 2024 reconciliation (2024) | D27: USD | E27: 0
A28: 65a5aa4d3c9840e32446690c | B28: Vicente Ramos | C28: US Payroll - May (2024) | D28: USD | E28: 1400 | F28: 45414
A29: 65a5aa4d3c9840e32446690c | B29: Vicente Ramos | C29: US Payroll - March (2024) | D29: USD | E29: 1650 | F29: 45358
A30: 65a5aa4d3c9840e32446690c | B30: Vicente Ramos | C30: US Payroll - February (2024) | D30: USD | E30: 1340 | F30: 45330
A31: 65a5aa4d3c9840e32446690c | B31: Vicente Ramos | C31: June Payroll - US (2024) | D31: USD | E31: 1254 | F31: 45442
A32: 65a5aa4d3c9840e32446690c | B32: Vicente Ramos | C32: Q1 2024 reconciliation (2024) | D32: USD | E32: 0
A33: 5c01d661da32c81a5929c928 | B33: Neil Graham | C33: US Payroll - March (2024) | D33: USD | E33: 10412.8 | F33: 45358
A34: 5c01d661da32c81a5929c928 | B34: Neil Graham | C34: US Payroll - February (2024) | D34: USD | E34: 9818.64 | F34: 45330
A35: 5c01d661da32c81a5929c928 | B35: Neil Graham | C35: April Payroll - US (2024) | D35: USD | E35: 10318.4 | F35: 45386
A36: 5c01d661da32c81a5929c928 | B36: Neil Graham | C36: Q2 2024 reconciliation (2024) | D36: USD | E36: 0
A37: 5c01d661da32c81a5929c928 | B37: Neil Graham | C37: January Payroll - US (2024) | D37: USD | E37: 10307.2 | F37: 45302
A38: 5c01d661da32c81a5929c928 | B38: Neil Graham | C38: US Payroll - May (2024) | D38: USD | E38: 10427.2 | F38: 45414
A39: 5c01d661da32c81a5929c928 | B39: Neil Graham | C39: June Payroll - US (2024) | D39: USD | E39: 10504 | F39: 45442
A40: 5c01d661da32c81a5929c928 | B40: Neil Graham | C40: Q1 2024 reconciliation (2024) | D40: USD | E40: 0
...

Sheet Sheet1
A1: Employee | B1: wage | C1: annual max | D1: Female | E1: Male | F1: 168600 | G1: fraction of year | H1: 0.5
A2: Claire Vogl | B2: =SUMIFS('ripping report '!E:E,'ripping report '!B:B,A2) -> 3733.75 | C2: =MIN(B2,F$1*H$1) -> 3733.75 | D2: 1
A3: JT Metcalf | B3: =SUMIFS('ripping report '!E:E,'ripping report '!B:B,A3) -> 43270 | C3: =MIN(B3,F$1*H$1) -> 43270 | E3: 1
A4: Colby Neeb | B4: =SUMIFS('ripping report '!E:E,'ripping report '!B:B,A4) -> 42131.13 | C4: =MIN(B4,F$1*H$1) -> 42131.13 | E4: 1
A5: Vicente Ramos | B5: =SUMIFS('ripping report '!E:E,'ripping report '!B:B,A5) -> 7164 | C5: =MIN(B5,F$1*H$1) -> 7164 | E5: 1
A6: Neil Graham | B6: =SUMIFS('ripping report '!E:E,'ripping report '!B:B,A6) -> 61788.24 | C6: =MIN(B6,F$1*H$1) -> 61788.24 | E6: 1
A7: Danny Hurlburt | B7: =SUMIFS('ripping report '!E:E,'ripping report '!B:B,A7) -> 56736.77 | C7: =MIN(B7,F$1*H$1) -> 56736.77 | E7: 1
A8: Jamie Gulden | B8: =SUMIFS('ripping report '!E:E,'ripping report '!B:B,A8) -> 71520 | C8: =MIN(B8,F$1*H$1) -> 71520 | E8: 1
A9: Eddie Thomas | B9: =SUMIFS('ripping report '!E:E,'ripping report '!B:B,A9) -> 46459.5 | C9: =MIN(B9,F$1*H$1) -> 46459.5 | E9: 1
A10: David McComb | B10: =SUMIFS('ripping report '!E:E,'ripping report '!B:B,A10) -> 110827.36 | C10: =MIN(B10,F$1*H$1) -> 84300 | E10: 1
D12: =SUM(D2:D11) -> 1 | E12: =SUM(E2:E11) -> 8
C14: =SUM(C2:C12) -> 417103.39 | F14: rate | G14: 0.0066 | I14: =C14*G14 -> 2752.8824
